Exception in thread Thread-3:
Traceback (most recent call last):
  File "/usr/lib/python2.7/threading.py", line 810, in __bootstrap_inner
    self.run()
  File "/usr/lib/python2.7/threading.py", line 763, in run
    self.__target(*self.__args, **self.__kwargs)
  File "dir_watcher.py", line 34, in worker
    subprocess.call(directory + "/run.sh")
  File "/usr/lib/python2.7/subprocess.py", line 522, in call
    return Popen(*popenargs, **kwargs).wait()
  File "/usr/lib/python2.7/subprocess.py", line 710, in __init__
    errread, errwrite)
  File "/usr/lib/python2.7/subprocess.py", line 1327, in _execute_child
    raise child_exception
OSError: [Errno 13] Permission denied

no run script here